[2024-03-23 09:00:58,688] {taskinstance.py:1179} INFO - Dependencies all met for <TaskInstance: load_data_to_postgres.load_to_postgres manual__2024-03-23T09:00:52.858345+00:00 [queued]>
[2024-03-23 09:00:58,691] {taskinstance.py:1179} INFO - Dependencies all met for <TaskInstance: load_data_to_postgres.load_to_postgres manual__2024-03-23T09:00:52.858345+00:00 [queued]>
[2024-03-23 09:00:58,691] {taskinstance.py:1376} INFO - 
--------------------------------------------------------------------------------
[2024-03-23 09:00:58,691] {taskinstance.py:1377} INFO - Starting attempt 1 of 1
[2024-03-23 09:00:58,691] {taskinstance.py:1378} INFO - 
--------------------------------------------------------------------------------
[2024-03-23 09:00:58,697] {taskinstance.py:1397} INFO - Executing <Task(PythonOperator): load_to_postgres> on 2024-03-23 09:00:52.858345+00:00
[2024-03-23 09:00:58,702] {standard_task_runner.py:52} INFO - Started process 1060 to run task
[2024-03-23 09:00:58,705] {standard_task_runner.py:79} INFO - Running: ['airflow', 'tasks', 'run', 'load_data_to_postgres', 'load_to_postgres', 'manual__2024-03-23T09:00:52.858345+00:00', '--job-id', '13', '--raw', '--subdir', 'DAGS_FOLDER/api_etl_dbt.py', '--cfg-path', '/tmp/tmptryiyoeg', '--error-file', '/tmp/tmpipfuce5n']
[2024-03-23 09:00:58,706] {standard_task_runner.py:80} INFO - Job 13: Subtask load_to_postgres
[2024-03-23 09:00:58,741] {task_command.py:371} INFO - Running <TaskInstance: load_data_to_postgres.load_to_postgres manual__2024-03-23T09:00:52.858345+00:00 [running]> on host 810364161d6b
[2024-03-23 09:00:58,770] {taskinstance.py:1591} INFO - Exporting the following env vars:
AIRFLOW_CTX_DAG_OWNER=airflow
AIRFLOW_CTX_DAG_ID=load_data_to_postgres
AIRFLOW_CTX_TASK_ID=load_to_postgres
AIRFLOW_CTX_EXECUTION_DATE=2024-03-23T09:00:52.858345+00:00
AIRFLOW_CTX_TRY_NUMBER=1
AIRFLOW_CTX_DAG_RUN_ID=manual__2024-03-23T09:00:52.858345+00:00
[2024-03-23 09:00:58,772] {taskinstance.py:1909} ERROR - Task failed with exception
Traceback (most recent call last):
  File "/home/airflow/.local/lib/python3.7/site-packages/airflow/operators/python.py", line 171, in execute
    return_value = self.execute_callable()
  File "/home/airflow/.local/lib/python3.7/site-packages/airflow/operators/python.py", line 189, in execute_callable
    return self.python_callable(*self.op_args, **self.op_kwargs)
  File "/opt/airflow/dags/api_etl_dbt.py", line 57, in load_to_postgres
    tbl_pemain_df = pd.read_json(tbl_pemain)
  File "/home/airflow/.local/lib/python3.7/site-packages/pandas/util/_decorators.py", line 207, in wrapper
    return func(*args, **kwargs)
  File "/home/airflow/.local/lib/python3.7/site-packages/pandas/util/_decorators.py", line 311, in wrapper
    return func(*args, **kwargs)
  File "/home/airflow/.local/lib/python3.7/site-packages/pandas/io/json/_json.py", line 614, in read_json
    return json_reader.read()
  File "/home/airflow/.local/lib/python3.7/site-packages/pandas/io/json/_json.py", line 748, in read
    obj = self._get_object_parser(self.data)
  File "/home/airflow/.local/lib/python3.7/site-packages/pandas/io/json/_json.py", line 770, in _get_object_parser
    obj = FrameParser(json, **kwargs).parse()
  File "/home/airflow/.local/lib/python3.7/site-packages/pandas/io/json/_json.py", line 885, in parse
    self._parse_no_numpy()
  File "/home/airflow/.local/lib/python3.7/site-packages/pandas/io/json/_json.py", line 1140, in _parse_no_numpy
    loads(json, precise_float=self.precise_float), dtype=None
ValueError: Unexpected character found when decoding 'true'
[2024-03-23 09:00:58,775] {taskinstance.py:1420} INFO - Marking task as FAILED. dag_id=load_data_to_postgres, task_id=load_to_postgres, execution_date=20240323T090052, start_date=20240323T090058, end_date=20240323T090058
[2024-03-23 09:00:58,780] {standard_task_runner.py:97} ERROR - Failed to execute job 13 for task load_to_postgres (Unexpected character found when decoding 'true'; 1060)
[2024-03-23 09:00:58,799] {local_task_job.py:156} INFO - Task exited with return code 1
[2024-03-23 09:00:58,808] {local_task_job.py:273} INFO - 0 downstream tasks scheduled from follow-on schedule check
