[2024-03-23T16:59:16.245+0000] {taskinstance.py:1979} INFO - Dependencies all met for dep_context=non-requeueable deps ti=<TaskInstance: load_data_to_postgres.load_to_postgres manual__2024-03-23T16:59:04.973098+00:00 [queued]>
[2024-03-23T16:59:16.248+0000] {taskinstance.py:1979} INFO - Dependencies all met for dep_context=requeueable deps ti=<TaskInstance: load_data_to_postgres.load_to_postgres manual__2024-03-23T16:59:04.973098+00:00 [queued]>
[2024-03-23T16:59:16.248+0000] {taskinstance.py:2193} INFO - Starting attempt 1 of 1
[2024-03-23T16:59:16.254+0000] {taskinstance.py:2217} INFO - Executing <Task(PythonOperator): load_to_postgres> on 2024-03-23 16:59:04.973098+00:00
[2024-03-23T16:59:16.264+0000] {standard_task_runner.py:60} INFO - Started process 597 to run task
[2024-03-23T16:59:16.268+0000] {standard_task_runner.py:87} INFO - Running: ['airflow', 'tasks', 'run', 'load_data_to_postgres', 'load_to_postgres', 'manual__2024-03-23T16:59:04.973098+00:00', '--job-id', '13', '--raw', '--subdir', 'DAGS_FOLDER/api_etl_dbt.py', '--cfg-path', '/tmp/tmpqkup8uaa']
[2024-03-23T16:59:16.269+0000] {standard_task_runner.py:88} INFO - Job 13: Subtask load_to_postgres
[2024-03-23T16:59:16.320+0000] {task_command.py:423} INFO - Running <TaskInstance: load_data_to_postgres.load_to_postgres manual__2024-03-23T16:59:04.973098+00:00 [running]> on host befec2369278
[2024-03-23T16:59:16.347+0000] {taskinstance.py:2513} INFO - Exporting env vars: AIRFLOW_CTX_DAG_OWNER='airflow' AIRFLOW_CTX_DAG_ID='load_data_to_postgres' AIRFLOW_CTX_TASK_ID='load_to_postgres' AIRFLOW_CTX_EXECUTION_DATE='2024-03-23T16:59:04.973098+00:00' AIRFLOW_CTX_TRY_NUMBER='1' AIRFLOW_CTX_DAG_RUN_ID='manual__2024-03-23T16:59:04.973098+00:00'
[2024-03-23T16:59:16.416+0000] {taskinstance.py:2731} ERROR - Task failed with exception
Traceback (most recent call last):
  File "/home/airflow/.local/lib/python3.8/site-packages/sqlalchemy/engine/base.py", line 1910, in _execute_context
    self.dialect.do_execute(
  File "/home/airflow/.local/lib/python3.8/site-packages/sqlalchemy/engine/default.py", line 736, in do_execute
    cursor.execute(statement, parameters)
psycopg2.errors.ActiveSqlTransaction: CREATE DATABASE cannot run inside a transaction block


The above exception was the direct cause of the following exception:

Traceback (most recent call last):
  File "/home/airflow/.local/lib/python3.8/site-packages/airflow/models/taskinstance.py", line 444, in _execute_task
    result = _execute_callable(context=context, **execute_callable_kwargs)
  File "/home/airflow/.local/lib/python3.8/site-packages/airflow/models/taskinstance.py", line 414, in _execute_callable
    return execute_callable(context=context, **execute_callable_kwargs)
  File "/home/airflow/.local/lib/python3.8/site-packages/airflow/operators/python.py", line 200, in execute
    return_value = self.execute_callable()
  File "/home/airflow/.local/lib/python3.8/site-packages/airflow/operators/python.py", line 217, in execute_callable
    return self.python_callable(*self.op_args, **self.op_kwargs)
  File "/opt/airflow/dags/api_etl_dbt.py", line 81, in load_to_postgres
    check_and_create_database(engine, database_name)
  File "/opt/airflow/dags/api_etl_dbt.py", line 59, in check_and_create_database
    engine.execute(f"CREATE DATABASE {database_name}")
  File "<string>", line 2, in execute
  File "/home/airflow/.local/lib/python3.8/site-packages/sqlalchemy/util/deprecations.py", line 468, in warned
    return fn(*args, **kwargs)
  File "/home/airflow/.local/lib/python3.8/site-packages/sqlalchemy/engine/base.py", line 3267, in execute
    return connection.execute(statement, *multiparams, **params)
  File "/home/airflow/.local/lib/python3.8/site-packages/sqlalchemy/engine/base.py", line 1370, in execute
    return self._exec_driver_sql(
  File "/home/airflow/.local/lib/python3.8/site-packages/sqlalchemy/engine/base.py", line 1674, in _exec_driver_sql
    ret = self._execute_context(
  File "/home/airflow/.local/lib/python3.8/site-packages/sqlalchemy/engine/base.py", line 1953, in _execute_context
    self._handle_dbapi_exception(
  File "/home/airflow/.local/lib/python3.8/site-packages/sqlalchemy/engine/base.py", line 2134, in _handle_dbapi_exception
    util.raise_(
  File "/home/airflow/.local/lib/python3.8/site-packages/sqlalchemy/util/compat.py", line 211, in raise_
    raise exception
  File "/home/airflow/.local/lib/python3.8/site-packages/sqlalchemy/engine/base.py", line 1910, in _execute_context
    self.dialect.do_execute(
  File "/home/airflow/.local/lib/python3.8/site-packages/sqlalchemy/engine/default.py", line 736, in do_execute
    cursor.execute(statement, parameters)
sqlalchemy.exc.InternalError: (psycopg2.errors.ActiveSqlTransaction) CREATE DATABASE cannot run inside a transaction block

[SQL: CREATE DATABASE etl_dbt_airflow]
(Background on this error at: https://sqlalche.me/e/14/2j85)
[2024-03-23T16:59:16.435+0000] {taskinstance.py:1149} INFO - Marking task as FAILED. dag_id=load_data_to_postgres, task_id=load_to_postgres, execution_date=20240323T165904, start_date=20240323T165916, end_date=20240323T165916
[2024-03-23T16:59:16.443+0000] {standard_task_runner.py:107} ERROR - Failed to execute job 13 for task load_to_postgres ((psycopg2.errors.ActiveSqlTransaction) CREATE DATABASE cannot run inside a transaction block

[SQL: CREATE DATABASE etl_dbt_airflow]
(Background on this error at: https://sqlalche.me/e/14/2j85); 597)
[2024-03-23T16:59:16.493+0000] {local_task_job_runner.py:234} INFO - Task exited with return code 1
[2024-03-23T16:59:16.500+0000] {taskinstance.py:3312} INFO - 0 downstream tasks scheduled from follow-on schedule check
