[2024-03-23T16:57:17.902+0000] {taskinstance.py:1979} INFO - Dependencies all met for dep_context=non-requeueable deps ti=<TaskInstance: load_data_to_postgres.load_to_postgres manual__2024-03-23T16:57:07.382646+00:00 [queued]>
[2024-03-23T16:57:17.907+0000] {taskinstance.py:1979} INFO - Dependencies all met for dep_context=requeueable deps ti=<TaskInstance: load_data_to_postgres.load_to_postgres manual__2024-03-23T16:57:07.382646+00:00 [queued]>
[2024-03-23T16:57:17.907+0000] {taskinstance.py:2193} INFO - Starting attempt 1 of 1
[2024-03-23T16:57:17.914+0000] {taskinstance.py:2217} INFO - Executing <Task(PythonOperator): load_to_postgres> on 2024-03-23 16:57:07.382646+00:00
[2024-03-23T16:57:17.930+0000] {standard_task_runner.py:60} INFO - Started process 477 to run task
[2024-03-23T16:57:17.947+0000] {standard_task_runner.py:87} INFO - Running: ['airflow', 'tasks', 'run', 'load_data_to_postgres', 'load_to_postgres', 'manual__2024-03-23T16:57:07.382646+00:00', '--job-id', '10', '--raw', '--subdir', 'DAGS_FOLDER/api_etl_dbt.py', '--cfg-path', '/tmp/tmpd1lwmv75']
[2024-03-23T16:57:17.961+0000] {standard_task_runner.py:88} INFO - Job 10: Subtask load_to_postgres
[2024-03-23T16:57:18.065+0000] {task_command.py:423} INFO - Running <TaskInstance: load_data_to_postgres.load_to_postgres manual__2024-03-23T16:57:07.382646+00:00 [running]> on host befec2369278
[2024-03-23T16:57:18.114+0000] {taskinstance.py:2513} INFO - Exporting env vars: AIRFLOW_CTX_DAG_OWNER='airflow' AIRFLOW_CTX_DAG_ID='load_data_to_postgres' AIRFLOW_CTX_TASK_ID='load_to_postgres' AIRFLOW_CTX_EXECUTION_DATE='2024-03-23T16:57:07.382646+00:00' AIRFLOW_CTX_TRY_NUMBER='1' AIRFLOW_CTX_DAG_RUN_ID='manual__2024-03-23T16:57:07.382646+00:00'
[2024-03-23T16:57:18.117+0000] {taskinstance.py:2731} ERROR - Task failed with exception
Traceback (most recent call last):
  File "/home/airflow/.local/lib/python3.8/site-packages/airflow/models/taskinstance.py", line 444, in _execute_task
    result = _execute_callable(context=context, **execute_callable_kwargs)
  File "/home/airflow/.local/lib/python3.8/site-packages/airflow/models/taskinstance.py", line 414, in _execute_callable
    return execute_callable(context=context, **execute_callable_kwargs)
  File "/home/airflow/.local/lib/python3.8/site-packages/airflow/operators/python.py", line 200, in execute
    return_value = self.execute_callable()
  File "/home/airflow/.local/lib/python3.8/site-packages/airflow/operators/python.py", line 217, in execute_callable
    return self.python_callable(*self.op_args, **self.op_kwargs)
  File "/opt/airflow/dags/api_etl_dbt.py", line 69, in load_to_postgres
    tbl_pemain_json, tbl_nationality_json, tbl_position_json = ti.xcom_pull(task_ids='transform_data')
TypeError: cannot unpack non-iterable NoneType object
[2024-03-23T16:57:18.119+0000] {taskinstance.py:1149} INFO - Marking task as FAILED. dag_id=load_data_to_postgres, task_id=load_to_postgres, execution_date=20240323T165707, start_date=20240323T165717, end_date=20240323T165718
[2024-03-23T16:57:18.123+0000] {standard_task_runner.py:107} ERROR - Failed to execute job 10 for task load_to_postgres (cannot unpack non-iterable NoneType object; 477)
[2024-03-23T16:57:18.135+0000] {local_task_job_runner.py:234} INFO - Task exited with return code 1
[2024-03-23T16:57:18.142+0000] {taskinstance.py:3312} INFO - 0 downstream tasks scheduled from follow-on schedule check
