[2024-03-23 08:58:54,319] {taskinstance.py:1179} INFO - Dependencies all met for <TaskInstance: load_data_to_postgres.transform_data manual__2024-03-23T08:58:49.076949+00:00 [queued]>
[2024-03-23 08:58:54,322] {taskinstance.py:1179} INFO - Dependencies all met for <TaskInstance: load_data_to_postgres.transform_data manual__2024-03-23T08:58:49.076949+00:00 [queued]>
[2024-03-23 08:58:54,323] {taskinstance.py:1376} INFO - 
--------------------------------------------------------------------------------
[2024-03-23 08:58:54,323] {taskinstance.py:1377} INFO - Starting attempt 1 of 1
[2024-03-23 08:58:54,323] {taskinstance.py:1378} INFO - 
--------------------------------------------------------------------------------
[2024-03-23 08:58:54,330] {taskinstance.py:1397} INFO - Executing <Task(PythonOperator): transform_data> on 2024-03-23 08:58:49.076949+00:00
[2024-03-23 08:58:54,338] {standard_task_runner.py:52} INFO - Started process 913 to run task
[2024-03-23 08:58:54,348] {standard_task_runner.py:79} INFO - Running: ['airflow', 'tasks', 'run', 'load_data_to_postgres', 'transform_data', 'manual__2024-03-23T08:58:49.076949+00:00', '--job-id', '9', '--raw', '--subdir', 'DAGS_FOLDER/api_etl_dbt.py', '--cfg-path', '/tmp/tmppugu7mzz', '--error-file', '/tmp/tmppg37vb1x']
[2024-03-23 08:58:54,350] {standard_task_runner.py:80} INFO - Job 9: Subtask transform_data
[2024-03-23 08:58:54,429] {task_command.py:371} INFO - Running <TaskInstance: load_data_to_postgres.transform_data manual__2024-03-23T08:58:49.076949+00:00 [running]> on host 810364161d6b
[2024-03-23 08:58:54,457] {taskinstance.py:1591} INFO - Exporting the following env vars:
AIRFLOW_CTX_DAG_OWNER=airflow
AIRFLOW_CTX_DAG_ID=load_data_to_postgres
AIRFLOW_CTX_TASK_ID=transform_data
AIRFLOW_CTX_EXECUTION_DATE=2024-03-23T08:58:49.076949+00:00
AIRFLOW_CTX_TRY_NUMBER=1
AIRFLOW_CTX_DAG_RUN_ID=manual__2024-03-23T08:58:49.076949+00:00
[2024-03-23 08:58:54,458] {taskinstance.py:1909} ERROR - Task failed with exception
Traceback (most recent call last):
  File "/home/airflow/.local/lib/python3.7/site-packages/airflow/operators/python.py", line 171, in execute
    return_value = self.execute_callable()
  File "/home/airflow/.local/lib/python3.7/site-packages/airflow/operators/python.py", line 189, in execute_callable
    return self.python_callable(*self.op_args, **self.op_kwargs)
TypeError: transform_data() missing 1 required positional argument: 'data'
[2024-03-23 08:58:54,460] {taskinstance.py:1420} INFO - Marking task as FAILED. dag_id=load_data_to_postgres, task_id=transform_data, execution_date=20240323T085849, start_date=20240323T085854, end_date=20240323T085854
[2024-03-23 08:58:54,464] {standard_task_runner.py:97} ERROR - Failed to execute job 9 for task transform_data (transform_data() missing 1 required positional argument: 'data'; 913)
[2024-03-23 08:58:54,486] {local_task_job.py:156} INFO - Task exited with return code 1
[2024-03-23 08:58:54,500] {local_task_job.py:273} INFO - 0 downstream tasks scheduled from follow-on schedule check
