[2024-03-23 16:21:01,030] {taskinstance.py:1179} INFO - Dependencies all met for <TaskInstance: load_data_to_postgres.load_to_postgres manual__2024-03-23T16:20:48.753074+00:00 [queued]>
[2024-03-23 16:21:01,036] {taskinstance.py:1179} INFO - Dependencies all met for <TaskInstance: load_data_to_postgres.load_to_postgres manual__2024-03-23T16:20:48.753074+00:00 [queued]>
[2024-03-23 16:21:01,036] {taskinstance.py:1376} INFO - 
--------------------------------------------------------------------------------
[2024-03-23 16:21:01,037] {taskinstance.py:1377} INFO - Starting attempt 1 of 1
[2024-03-23 16:21:01,037] {taskinstance.py:1378} INFO - 
--------------------------------------------------------------------------------
[2024-03-23 16:21:01,067] {taskinstance.py:1397} INFO - Executing <Task(PythonOperator): load_to_postgres> on 2024-03-23 16:20:48.753074+00:00
[2024-03-23 16:21:01,075] {standard_task_runner.py:52} INFO - Started process 604 to run task
[2024-03-23 16:21:01,102] {standard_task_runner.py:79} INFO - Running: ['airflow', 'tasks', 'run', 'load_data_to_postgres', 'load_to_postgres', 'manual__2024-03-23T16:20:48.753074+00:00', '--job-id', '16', '--raw', '--subdir', 'DAGS_FOLDER/api_etl_dbt.py', '--cfg-path', '/tmp/tmptizxf65q', '--error-file', '/tmp/tmp7jr3whep']
[2024-03-23 16:21:01,104] {standard_task_runner.py:80} INFO - Job 16: Subtask load_to_postgres
[2024-03-23 16:21:01,144] {task_command.py:371} INFO - Running <TaskInstance: load_data_to_postgres.load_to_postgres manual__2024-03-23T16:20:48.753074+00:00 [running]> on host eb25ddb3314a
[2024-03-23 16:21:01,175] {taskinstance.py:1591} INFO - Exporting the following env vars:
AIRFLOW_CTX_DAG_OWNER=airflow
AIRFLOW_CTX_DAG_ID=load_data_to_postgres
AIRFLOW_CTX_TASK_ID=load_to_postgres
AIRFLOW_CTX_EXECUTION_DATE=2024-03-23T16:20:48.753074+00:00
AIRFLOW_CTX_TRY_NUMBER=1
AIRFLOW_CTX_DAG_RUN_ID=manual__2024-03-23T16:20:48.753074+00:00
[2024-03-23 16:21:01,176] {logging_mixin.py:115} INFO - tbl_pemain ini tbl_pemain_json
[2024-03-23 16:21:01,176] {taskinstance.py:1909} ERROR - Task failed with exception
Traceback (most recent call last):
  File "/home/airflow/.local/lib/python3.7/site-packages/airflow/operators/python.py", line 171, in execute
    return_value = self.execute_callable()
  File "/home/airflow/.local/lib/python3.7/site-packages/airflow/operators/python.py", line 189, in execute_callable
    return self.python_callable(*self.op_args, **self.op_kwargs)
  File "/opt/airflow/dags/api_etl_dbt.py", line 69, in load_to_postgres
    tbl_pemain_df = pd.DataFrame(tbl_pemain_json)
  File "/home/airflow/.local/lib/python3.7/site-packages/pandas/core/frame.py", line 730, in __init__
    raise ValueError("DataFrame constructor not properly called!")
ValueError: DataFrame constructor not properly called!
[2024-03-23 16:21:01,182] {taskinstance.py:1420} INFO - Marking task as FAILED. dag_id=load_data_to_postgres, task_id=load_to_postgres, execution_date=20240323T162048, start_date=20240323T162101, end_date=20240323T162101
[2024-03-23 16:21:01,186] {standard_task_runner.py:97} ERROR - Failed to execute job 16 for task load_to_postgres (DataFrame constructor not properly called!; 604)
[2024-03-23 16:21:01,197] {local_task_job.py:156} INFO - Task exited with return code 1
[2024-03-23 16:21:01,213] {local_task_job.py:273} INFO - 0 downstream tasks scheduled from follow-on schedule check
