[2024-03-23 15:22:03,849] {taskinstance.py:1179} INFO - Dependencies all met for <TaskInstance: load_data_to_postgres.load_to_postgres manual__2024-03-23T15:21:56.509415+00:00 [queued]>
[2024-03-23 15:22:03,858] {taskinstance.py:1179} INFO - Dependencies all met for <TaskInstance: load_data_to_postgres.load_to_postgres manual__2024-03-23T15:21:56.509415+00:00 [queued]>
[2024-03-23 15:22:03,858] {taskinstance.py:1376} INFO - 
--------------------------------------------------------------------------------
[2024-03-23 15:22:03,858] {taskinstance.py:1377} INFO - Starting attempt 1 of 1
[2024-03-23 15:22:03,859] {taskinstance.py:1378} INFO - 
--------------------------------------------------------------------------------
[2024-03-23 15:22:03,869] {taskinstance.py:1397} INFO - Executing <Task(PythonOperator): load_to_postgres> on 2024-03-23 15:21:56.509415+00:00
[2024-03-23 15:22:03,876] {standard_task_runner.py:52} INFO - Started process 5850 to run task
[2024-03-23 15:22:03,880] {standard_task_runner.py:79} INFO - Running: ['airflow', 'tasks', 'run', 'load_data_to_postgres', 'load_to_postgres', 'manual__2024-03-23T15:21:56.509415+00:00', '--job-id', '19', '--raw', '--subdir', 'DAGS_FOLDER/api_etl_dbt.py', '--cfg-path', '/tmp/tmpd3desb5w', '--error-file', '/tmp/tmpu314guq6']
[2024-03-23 15:22:03,880] {standard_task_runner.py:80} INFO - Job 19: Subtask load_to_postgres
[2024-03-23 15:22:03,906] {task_command.py:371} INFO - Running <TaskInstance: load_data_to_postgres.load_to_postgres manual__2024-03-23T15:21:56.509415+00:00 [running]> on host 810364161d6b
[2024-03-23 15:22:03,941] {taskinstance.py:1591} INFO - Exporting the following env vars:
AIRFLOW_CTX_DAG_OWNER=airflow
AIRFLOW_CTX_DAG_ID=load_data_to_postgres
AIRFLOW_CTX_TASK_ID=load_to_postgres
AIRFLOW_CTX_EXECUTION_DATE=2024-03-23T15:21:56.509415+00:00
AIRFLOW_CTX_TRY_NUMBER=1
AIRFLOW_CTX_DAG_RUN_ID=manual__2024-03-23T15:21:56.509415+00:00
[2024-03-23 15:22:03,942] {logging_mixin.py:115} WARNING - --- Logging error ---
[2024-03-23 15:22:03,944] {logging_mixin.py:115} WARNING - Traceback (most recent call last):
[2024-03-23 15:22:03,944] {logging_mixin.py:115} WARNING -   File "/opt/airflow/dags/api_etl_dbt.py", line 68, in load_to_postgres
    tbl_pemain_df = pd.read_json(tbl_pemain_json)
[2024-03-23 15:22:03,944] {logging_mixin.py:115} WARNING -   File "/home/airflow/.local/lib/python3.7/site-packages/pandas/util/_decorators.py", line 207, in wrapper
    return func(*args, **kwargs)
[2024-03-23 15:22:03,944] {logging_mixin.py:115} WARNING -   File "/home/airflow/.local/lib/python3.7/site-packages/pandas/util/_decorators.py", line 311, in wrapper
    return func(*args, **kwargs)
[2024-03-23 15:22:03,944] {logging_mixin.py:115} WARNING -   File "/home/airflow/.local/lib/python3.7/site-packages/pandas/io/json/_json.py", line 614, in read_json
    return json_reader.read()
[2024-03-23 15:22:03,944] {logging_mixin.py:115} WARNING -   File "/home/airflow/.local/lib/python3.7/site-packages/pandas/io/json/_json.py", line 748, in read
    obj = self._get_object_parser(self.data)
[2024-03-23 15:22:03,945] {logging_mixin.py:115} WARNING -   File "/home/airflow/.local/lib/python3.7/site-packages/pandas/io/json/_json.py", line 770, in _get_object_parser
    obj = FrameParser(json, **kwargs).parse()
[2024-03-23 15:22:03,945] {logging_mixin.py:115} WARNING -   File "/home/airflow/.local/lib/python3.7/site-packages/pandas/io/json/_json.py", line 885, in parse
    self._parse_no_numpy()
[2024-03-23 15:22:03,945] {logging_mixin.py:115} WARNING -   File "/home/airflow/.local/lib/python3.7/site-packages/pandas/io/json/_json.py", line 1140, in _parse_no_numpy
    loads(json, precise_float=self.precise_float), dtype=None
[2024-03-23 15:22:03,945] {logging_mixin.py:115} WARNING - ValueError: Unexpected character found when decoding 'true'
[2024-03-23 15:22:03,945] {logging_mixin.py:115} WARNING - 
During handling of the above exception, another exception occurred:
[2024-03-23 15:22:03,945] {logging_mixin.py:115} WARNING - Traceback (most recent call last):
[2024-03-23 15:22:03,945] {logging_mixin.py:115} WARNING -   File "/usr/local/lib/python3.7/logging/__init__.py", line 1025, in emit
    msg = self.format(record)
[2024-03-23 15:22:03,945] {logging_mixin.py:115} WARNING -   File "/usr/local/lib/python3.7/logging/__init__.py", line 869, in format
    return fmt.format(record)
[2024-03-23 15:22:03,945] {logging_mixin.py:115} WARNING -   File "/usr/local/lib/python3.7/logging/__init__.py", line 608, in format
    record.message = record.getMessage()
[2024-03-23 15:22:03,945] {logging_mixin.py:115} WARNING -   File "/usr/local/lib/python3.7/logging/__init__.py", line 369, in getMessage
    msg = msg % self.args
[2024-03-23 15:22:03,945] {logging_mixin.py:115} WARNING - TypeError: not all arguments converted during string formatting
[2024-03-23 15:22:03,946] {logging_mixin.py:115} WARNING - Call stack:
[2024-03-23 15:22:03,950] {logging_mixin.py:115} WARNING -   File "/home/airflow/.local/bin/airflow", line 8, in <module>
    sys.exit(main())
[2024-03-23 15:22:03,950] {logging_mixin.py:115} WARNING -   File "/home/airflow/.local/lib/python3.7/site-packages/airflow/__main__.py", line 38, in main
    args.func(args)
[2024-03-23 15:22:03,950] {logging_mixin.py:115} WARNING -   File "/home/airflow/.local/lib/python3.7/site-packages/airflow/cli/cli_parser.py", line 51, in command
    return func(*args, **kwargs)
[2024-03-23 15:22:03,950] {logging_mixin.py:115} WARNING -   File "/home/airflow/.local/lib/python3.7/site-packages/airflow/utils/cli.py", line 99, in wrapper
    return f(*args, **kwargs)
[2024-03-23 15:22:03,950] {logging_mixin.py:115} WARNING -   File "/home/airflow/.local/lib/python3.7/site-packages/airflow/cli/commands/task_command.py", line 377, in task_run
    _run_task_by_selected_method(args, dag, ti)
[2024-03-23 15:22:03,950] {logging_mixin.py:115} WARNING -   File "/home/airflow/.local/lib/python3.7/site-packages/airflow/cli/commands/task_command.py", line 183, in _run_task_by_selected_method
    _run_task_by_local_task_job(args, ti)
[2024-03-23 15:22:03,951] {logging_mixin.py:115} WARNING -   File "/home/airflow/.local/lib/python3.7/site-packages/airflow/cli/commands/task_command.py", line 241, in _run_task_by_local_task_job
    run_job.run()
[2024-03-23 15:22:03,951] {logging_mixin.py:115} WARNING -   File "/home/airflow/.local/lib/python3.7/site-packages/airflow/jobs/base_job.py", line 244, in run
    self._execute()
[2024-03-23 15:22:03,951] {logging_mixin.py:115} WARNING -   File "/home/airflow/.local/lib/python3.7/site-packages/airflow/jobs/local_task_job.py", line 105, in _execute
    self.task_runner.start()
[2024-03-23 15:22:03,951] {logging_mixin.py:115} WARNING -   File "/home/airflow/.local/lib/python3.7/site-packages/airflow/task/task_runner/standard_task_runner.py", line 41, in start
    self.process = self._start_by_fork()
[2024-03-23 15:22:03,951] {logging_mixin.py:115} WARNING -   File "/home/airflow/.local/lib/python3.7/site-packages/airflow/task/task_runner/standard_task_runner.py", line 88, in _start_by_fork
    args.func(args, dag=self.dag)
[2024-03-23 15:22:03,951] {logging_mixin.py:115} WARNING -   File "/home/airflow/.local/lib/python3.7/site-packages/airflow/cli/cli_parser.py", line 51, in command
    return func(*args, **kwargs)
[2024-03-23 15:22:03,951] {logging_mixin.py:115} WARNING -   File "/home/airflow/.local/lib/python3.7/site-packages/airflow/utils/cli.py", line 99, in wrapper
    return f(*args, **kwargs)
[2024-03-23 15:22:03,951] {logging_mixin.py:115} WARNING -   File "/home/airflow/.local/lib/python3.7/site-packages/airflow/cli/commands/task_command.py", line 377, in task_run
    _run_task_by_selected_method(args, dag, ti)
[2024-03-23 15:22:03,951] {logging_mixin.py:115} WARNING -   File "/home/airflow/.local/lib/python3.7/site-packages/airflow/cli/commands/task_command.py", line 185, in _run_task_by_selected_method
    _run_raw_task(args, ti)
[2024-03-23 15:22:03,951] {logging_mixin.py:115} WARNING -   File "/home/airflow/.local/lib/python3.7/site-packages/airflow/cli/commands/task_command.py", line 262, in _run_raw_task
    error_file=args.error_file,
[2024-03-23 15:22:03,951] {logging_mixin.py:115} WARNING -   File "/home/airflow/.local/lib/python3.7/site-packages/airflow/utils/session.py", line 71, in wrapper
    return func(*args, session=session, **kwargs)
[2024-03-23 15:22:03,951] {logging_mixin.py:115} WARNING -   File "/home/airflow/.local/lib/python3.7/site-packages/airflow/models/taskinstance.py", line 1471, in _run_raw_task
    self._execute_task_with_callbacks(context, test_mode)
[2024-03-23 15:22:03,952] {logging_mixin.py:115} WARNING -   File "/home/airflow/.local/lib/python3.7/site-packages/airflow/models/taskinstance.py", line 1618, in _execute_task_with_callbacks
    result = self._execute_task(context, task_orig)
[2024-03-23 15:22:03,952] {logging_mixin.py:115} WARNING -   File "/home/airflow/.local/lib/python3.7/site-packages/airflow/models/taskinstance.py", line 1679, in _execute_task
    result = execute_callable(context=context)
[2024-03-23 15:22:03,952] {logging_mixin.py:115} WARNING -   File "/home/airflow/.local/lib/python3.7/site-packages/airflow/operators/python.py", line 171, in execute
    return_value = self.execute_callable()
[2024-03-23 15:22:03,952] {logging_mixin.py:115} WARNING -   File "/home/airflow/.local/lib/python3.7/site-packages/airflow/operators/python.py", line 189, in execute_callable
    return self.python_callable(*self.op_args, **self.op_kwargs)
[2024-03-23 15:22:03,952] {logging_mixin.py:115} WARNING -   File "/opt/airflow/dags/api_etl_dbt.py", line 86, in load_to_postgres
    logging.error(e, "Something went wrong")
[2024-03-23 15:22:03,952] {logging_mixin.py:115} WARNING -   File "/usr/local/lib/python3.7/logging/__init__.py", line 1959, in error
    root.error(msg, *args, **kwargs)
[2024-03-23 15:22:03,952] {logging_mixin.py:115} WARNING -   File "/usr/local/lib/python3.7/logging/__init__.py", line 1407, in error
    self._log(ERROR, msg, args, **kwargs)
[2024-03-23 15:22:03,952] {logging_mixin.py:115} WARNING -   File "/usr/local/lib/python3.7/logging/__init__.py", line 1514, in _log
    self.handle(record)
[2024-03-23 15:22:03,952] {logging_mixin.py:115} WARNING -   File "/usr/local/lib/python3.7/logging/__init__.py", line 1524, in handle
    self.callHandlers(record)
[2024-03-23 15:22:03,952] {logging_mixin.py:115} WARNING -   File "/usr/local/lib/python3.7/logging/__init__.py", line 1586, in callHandlers
    hdlr.handle(record)
[2024-03-23 15:22:03,952] {logging_mixin.py:115} WARNING -   File "/usr/local/lib/python3.7/logging/__init__.py", line 894, in handle
    self.emit(record)
[2024-03-23 15:22:03,952] {logging_mixin.py:115} WARNING -   File "/home/airflow/.local/lib/python3.7/site-packages/airflow/utils/log/file_task_handler.py", line 71, in emit
    self.handler.emit(record)
[2024-03-23 15:22:03,952] {logging_mixin.py:115} WARNING - Message: ValueError("Unexpected character found when decoding 'true'")
Arguments: ('Something went wrong',)
[2024-03-23 15:22:03,953] {python.py:173} INFO - Done. Returned value was: None
[2024-03-23 15:22:03,956] {taskinstance.py:1420} INFO - Marking task as SUCCESS. dag_id=load_data_to_postgres, task_id=load_to_postgres, execution_date=20240323T152156, start_date=20240323T152203, end_date=20240323T152203
[2024-03-23 15:22:03,979] {local_task_job.py:156} INFO - Task exited with return code 0
[2024-03-23 15:22:03,988] {local_task_job.py:273} INFO - 0 downstream tasks scheduled from follow-on schedule check
