[2024-03-23T16:52:51.156+0000] {taskinstance.py:1979} INFO - Dependencies all met for dep_context=non-requeueable deps ti=<TaskInstance: load_data_to_postgres.load_to_postgres manual__2024-03-23T16:51:11.182402+00:00 [queued]>
[2024-03-23T16:52:51.355+0000] {taskinstance.py:1979} INFO - Dependencies all met for dep_context=requeueable deps ti=<TaskInstance: load_data_to_postgres.load_to_postgres manual__2024-03-23T16:51:11.182402+00:00 [queued]>
[2024-03-23T16:52:51.355+0000] {taskinstance.py:2193} INFO - Starting attempt 1 of 1
[2024-03-23T16:52:51.492+0000] {taskinstance.py:2217} INFO - Executing <Task(PythonOperator): load_to_postgres> on 2024-03-23 16:51:11.182402+00:00
[2024-03-23T16:52:51.654+0000] {standard_task_runner.py:60} INFO - Started process 258 to run task
[2024-03-23T16:52:51.816+0000] {standard_task_runner.py:87} INFO - Running: ['airflow', 'tasks', 'run', 'load_data_to_postgres', 'load_to_postgres', 'manual__2024-03-23T16:51:11.182402+00:00', '--job-id', '4', '--raw', '--subdir', 'DAGS_FOLDER/api_etl_dbt.py', '--cfg-path', '/tmp/tmpywmiyxtx']
[2024-03-23T16:52:51.979+0000] {standard_task_runner.py:88} INFO - Job 4: Subtask load_to_postgres
[2024-03-23T16:52:53.251+0000] {task_command.py:423} INFO - Running <TaskInstance: load_data_to_postgres.load_to_postgres manual__2024-03-23T16:51:11.182402+00:00 [running]> on host befec2369278
[2024-03-23T16:52:54.949+0000] {taskinstance.py:2513} INFO - Exporting env vars: AIRFLOW_CTX_DAG_OWNER='airflow' AIRFLOW_CTX_DAG_ID='load_data_to_postgres' AIRFLOW_CTX_TASK_ID='load_to_postgres' AIRFLOW_CTX_EXECUTION_DATE='2024-03-23T16:51:11.182402+00:00' AIRFLOW_CTX_TRY_NUMBER='1' AIRFLOW_CTX_DAG_RUN_ID='manual__2024-03-23T16:51:11.182402+00:00'
[2024-03-23T16:52:55.109+0000] {taskinstance.py:2731} ERROR - Task failed with exception
Traceback (most recent call last):
  File "/home/airflow/.local/lib/python3.8/site-packages/airflow/models/taskinstance.py", line 444, in _execute_task
    result = _execute_callable(context=context, **execute_callable_kwargs)
  File "/home/airflow/.local/lib/python3.8/site-packages/airflow/models/taskinstance.py", line 414, in _execute_callable
    return execute_callable(context=context, **execute_callable_kwargs)
  File "/home/airflow/.local/lib/python3.8/site-packages/airflow/operators/python.py", line 200, in execute
    return_value = self.execute_callable()
  File "/home/airflow/.local/lib/python3.8/site-packages/airflow/operators/python.py", line 217, in execute_callable
    return self.python_callable(*self.op_args, **self.op_kwargs)
  File "/opt/airflow/dags/api_etl_dbt.py", line 68, in load_to_postgres
    tbl_pemain_json, tbl_nationality_json, tbl_position_json = ti.xcom_pull(task_ids='transform_data')
TypeError: cannot unpack non-iterable NoneType object
[2024-03-23T16:52:55.142+0000] {taskinstance.py:1149} INFO - Marking task as FAILED. dag_id=load_data_to_postgres, task_id=load_to_postgres, execution_date=20240323T165111, start_date=20240323T165251, end_date=20240323T165255
[2024-03-23T16:52:55.221+0000] {standard_task_runner.py:107} ERROR - Failed to execute job 4 for task load_to_postgres (cannot unpack non-iterable NoneType object; 258)
[2024-03-23T16:52:55.358+0000] {local_task_job_runner.py:234} INFO - Task exited with return code 1
[2024-03-23T16:52:55.716+0000] {taskinstance.py:3312} INFO - 0 downstream tasks scheduled from follow-on schedule check
