[2024-03-23T16:55:59.713+0000] {taskinstance.py:1979} INFO - Dependencies all met for dep_context=non-requeueable deps ti=<TaskInstance: load_data_to_postgres.transform_data manual__2024-03-23T16:55:50.977157+00:00 [queued]>
[2024-03-23T16:55:59.717+0000] {taskinstance.py:1979} INFO - Dependencies all met for dep_context=requeueable deps ti=<TaskInstance: load_data_to_postgres.transform_data manual__2024-03-23T16:55:50.977157+00:00 [queued]>
[2024-03-23T16:55:59.717+0000] {taskinstance.py:2193} INFO - Starting attempt 1 of 1
[2024-03-23T16:55:59.725+0000] {taskinstance.py:2217} INFO - Executing <Task(PythonOperator): transform_data> on 2024-03-23 16:55:50.977157+00:00
[2024-03-23T16:55:59.737+0000] {standard_task_runner.py:60} INFO - Started process 379 to run task
[2024-03-23T16:55:59.741+0000] {standard_task_runner.py:87} INFO - Running: ['airflow', 'tasks', 'run', 'load_data_to_postgres', 'transform_data', 'manual__2024-03-23T16:55:50.977157+00:00', '--job-id', '6', '--raw', '--subdir', 'DAGS_FOLDER/api_etl_dbt.py', '--cfg-path', '/tmp/tmpawdeaf3m']
[2024-03-23T16:55:59.743+0000] {standard_task_runner.py:88} INFO - Job 6: Subtask transform_data
[2024-03-23T16:55:59.797+0000] {task_command.py:423} INFO - Running <TaskInstance: load_data_to_postgres.transform_data manual__2024-03-23T16:55:50.977157+00:00 [running]> on host befec2369278
[2024-03-23T16:55:59.866+0000] {taskinstance.py:2513} INFO - Exporting env vars: AIRFLOW_CTX_DAG_OWNER='airflow' AIRFLOW_CTX_DAG_ID='load_data_to_postgres' AIRFLOW_CTX_TASK_ID='transform_data' AIRFLOW_CTX_EXECUTION_DATE='2024-03-23T16:55:50.977157+00:00' AIRFLOW_CTX_TRY_NUMBER='1' AIRFLOW_CTX_DAG_RUN_ID='manual__2024-03-23T16:55:50.977157+00:00'
[2024-03-23T16:55:59.890+0000] {taskinstance.py:2731} ERROR - Task failed with exception
Traceback (most recent call last):
  File "/home/airflow/.local/lib/python3.8/site-packages/airflow/models/taskinstance.py", line 444, in _execute_task
    result = _execute_callable(context=context, **execute_callable_kwargs)
  File "/home/airflow/.local/lib/python3.8/site-packages/airflow/models/taskinstance.py", line 414, in _execute_callable
    return execute_callable(context=context, **execute_callable_kwargs)
  File "/home/airflow/.local/lib/python3.8/site-packages/airflow/operators/python.py", line 200, in execute
    return_value = self.execute_callable()
  File "/home/airflow/.local/lib/python3.8/site-packages/airflow/operators/python.py", line 217, in execute_callable
    return self.python_callable(*self.op_args, **self.op_kwargs)
  File "/opt/airflow/dags/api_etl_dbt.py", line 37, in transform_data
    tbl_pemain_df = tbl_pemain_df.append({
  File "/home/airflow/.local/lib/python3.8/site-packages/pandas/core/generic.py", line 5989, in __getattr__
    return object.__getattribute__(self, name)
AttributeError: 'DataFrame' object has no attribute 'append'
[2024-03-23T16:55:59.898+0000] {taskinstance.py:1149} INFO - Marking task as FAILED. dag_id=load_data_to_postgres, task_id=transform_data, execution_date=20240323T165550, start_date=20240323T165559, end_date=20240323T165559
[2024-03-23T16:55:59.906+0000] {standard_task_runner.py:107} ERROR - Failed to execute job 6 for task transform_data ('DataFrame' object has no attribute 'append'; 379)
[2024-03-23T16:55:59.934+0000] {local_task_job_runner.py:234} INFO - Task exited with return code 1
[2024-03-23T16:55:59.942+0000] {taskinstance.py:3312} INFO - 0 downstream tasks scheduled from follow-on schedule check
